Workbook

Sheet Net ERs
A2: Axam Project Area: | B2: =45000*0.2 -> 9000
F3: QA1 | I3: QA3
A4: Year | B4: Project | C4: Baseline | D4: Difference | F4: Est ERs | G4: Est Error | I4: N2O Emissions Burning (Baseline only) | J4: CH4 Emissions Burning (Baseline only) | K4: Fossil Fuel (Baseline) | L4: Fossil Fuel (Project) | M4: Fertilizer Usage (Baseline) | N4: Fertilizer Usage (Project) | O4: Total (QA3 Emissions)
A5: Units ----> | B5: SOC_t_C_ha | C5: SOC_t_C_ha | D5: SOC_t_C_ha | F5: tCO2e | G5: tCO2e | I5: tCO2e | J5: tCO2e | K5: tCO2e | L5: tCO2e | M5: tCO2e | N5: tCO2e | O5: tCO2e
A6: 1 (initialization) | B6: 36.164813 | C6: 28.225958 | D6: =(B6 -C6) -> 7.9388545 | F6: =D6*$B$2*44/12 -> 261982.2 | Q6: Vintage period | R6: Estimated baseline emissions (tCO2e) | S6: Estimated project emissions (tCO2e) | T6: Estimated leakage emissions (tCO2e) | U6: Estimated buffer pool allocation (tCO2e) | V6: Estimated reduction VCUs (tCO2e) | W6: Estimated removal VCUs (tCO2e) | X6: Estimated total VCUs (tCO2e)
A7: 2025 | B7: 36.164814 | C7: 28.225957 | D7: =(B7 -C7) -> 7.9388564 | F7: =D7*$B$2*44/12 -> 261982.26 | G7: =SQRT('Sampling & Combined Error'!$E$14)*$B$2*44/12 -> 17330.613 | I7: 107.493 | J7: 187.7472 | K7: 1554.4977 | L7: 1107.5355 | M7: 6085.8626 | N7: 3042.9313 | O7: =(N7+L7)-(I7+J7+K7+M7) -> -3785.1337 | Q7: 2025 | R7: =SUM(I7,J7,K7,M7) -> 7935.6005 | S7: =SUM(L7,N7) -> 4150.4668 | T7: 0 | U7: =(W7+V7)*0.175 -> 43476.437 | V7: =R7-S7 -> 3785.1337 | W7: =F7-G7 -> 244651.65 | X7: =W7+V7-U7 -> 204960.35
A8: 2026 | B8: 36.164815 | C8: 28.619949 | D8: =(B8 -C8) -> 7.5448661 | F8: =D8*$B$2*44/12 -> 248980.58 | G8: =SQRT('Sampling & Combined Error'!$E$14)*$B$2*44/12 -> 17330.613 | I8: 107.493 | J8: 187.7472 | K8: 1554.4977 | L8: 1107.5355 | M8: 6085.8626 | N8: 3042.9313 | O8: =(N8+L8)-(I8+J8+K8+M8) -> -3785.1337 | Q8: 2026 | R8: =SUM(I8,J8,K8,M8) -> 7935.6005 | S8: =SUM(L8,N8) -> 4150.4668 | T8: 1 | U8: =(W8+V8)*0.175 -> 41201.143 | V8: =R8-S8 -> 3785.1337 | W8: =F8-G8 -> 231649.97 | X8: =W8+V8-U8 -> 194233.96
A9: 2027 | B9: 36.164816 | C9: 28.246774 | D9: =(B9 -C9) -> 7.9180418 | F9: =D9*$B$2*44/12 -> 261295.38 | G9: =SQRT('Sampling & Combined Error'!$E$14)*$B$2*44/12 -> 17330.613 | I9: 107.493 | J9: 187.7472 | K9: 1554.4977 | L9: 1107.5355 | M9: 6085.8626 | N9: 3042.9313 | O9: =(N9+L9)-(I9+J9+K9+M9) -> -3785.1337 | Q9: 2027 | R9: =SUM(I9,J9,K9,M9) -> 7935.6005 | S9: =SUM(L9,N9) -> 4150.4668 | T9: 2 | U9: =(W9+V9)*0.175 -> 43356.233 | V9: =R9-S9 -> 3785.1337 | W9: =F9-G9 -> 243964.77 | X9: =W9+V9-U9 -> 204393.67
A10: 2028 | B10: 36.164817 | C10: 28.240847 | D10: =(B10 -C10) -> 7.9239695 | F10: =D10*$B$2*44/12 -> 261490.99 | G10: =SQRT('Sampling & Combined Error'!$E$14)*$B$2*44/12 -> 17330.613 | I10: 107.493 | J10: 187.7472 | K10: 1554.4977 | L10: 1107.5355 | M10: 6085.8626 | N10: 3042.9313 | O10: =(N10+L10)-(I10+J10+K10+M10) -> -3785.1337 | Q10: 2028 | R10: =SUM(I10,J10,K10,M10) -> 7935.6005 | S10: =SUM(L10,N10) -> 4150.4668 | T10: 3 | U10: =(W10+V10)*0.175 -> 43390.465 | V10: =R10-S10 -> 3785.1337 | W10: =F10-G10 -> 244160.38 | X10: =W10+V10-U10 -> 204555.05
A11: 2029 | B11: 36.164818 | C11: 28.236693 | D11: =(B11 -C11) -> 7.9281249 | F11: =D11*$B$2*44/12 -> 261628.12 | G11: =SQRT('Sampling & Combined Error'!$E$14)*$B$2*44/12 -> 17330.613 | I11: 107.493 | J11: 187.7472 | K11: 1554.4977 | L11: 1107.5355 | M11: 6085.8626 | N11: 3042.9313 | O11: =(N11+L11)-(I11+J11+K11+M11) -> -3785.1337 | Q11: 2029 | R11: =SUM(I11,J11,K11,M11) -> 7935.6005 | S11: =SUM(L11,N11) -> 4150.4668 | T11: 4 | U11: =(W11+V11)*0.175 -> 43414.462 | V11: =R11-S11 -> 3785.1337 | W11: =F11-G11 -> 244297.51 | X11: =W11+V11-U11 -> 204668.18
A12: 2030 | B12: 36.164819 | C12: 28.233756 | D12: =(B12 -C12) -> 7.9310624 | F12: =D12*$B$2*44/12 -> 261725.06 | G12: =SQRT('Sampling & Combined Error'!$E$14)*$B$2*44/12 -> 17330.613 | I12: 107.493 | J12: 187.7472 | K12: 1554.4977 | L12: 1107.5355 | M12: 6085.8626 | N12: 3042.9313 | O12: =(N12+L12)-(I12+J12+K12+M12) -> -3785.1337 | Q12: 2030 | R12: =SUM(I12,J12,K12,M12) -> 7935.6005 | S12: =SUM(L12,N12) -> 4150.4668 | T12: 5 | U12: =(W12+V12)*0.175 -> 43431.427 | V12: =R12-S12 -> 3785.1337 | W12: =F12-G12 -> 244394.45 | X12: =W12+V12-U12 -> 204748.15
A13: 2031 | B13: 36.164819 | C13: 28.231669 | D13: =(B13 -C13) -> 7.9331508 | F13: =D13*$B$2*44/12 -> 261793.98 | G13: =SQRT('Sampling & Combined Error'!$E$14)*$B$2*44/12 -> 17330.613 | I13: 107.493 | J13: 187.7472 | K13: 1554.4977 | L13: 1107.5355 | M13: 6085.8626 | N13: 3042.9313 | O13: =(N13+L13)-(I13+J13+K13+M13) -> -3785.1337 | Q13: 2031 | R13: =SUM(I13,J13,K13,M13) -> 7935.6005 | S13: =SUM(L13,N13) -> 4150.4668 | T13: 6 | U13: =(W13+V13)*0.175 -> 43443.487 | V13: =R13-S13 -> 3785.1337 | W13: =F13-G13 -> 244463.36 | X13: =W13+V13-U13 -> 204805.01
A14: 2032 | B14: 36.16482 | C14: 28.230178 | D14: =(B14 -C14) -> 7.9346421 | F14: =D14*$B$2*44/12 -> 261843.19 | G14: =SQRT('Sampling & Combined Error'!$E$14)*$B$2*44/12 -> 17330.613 | I14: 107.493 | J14: 187.7472 | K14: 1554.4977 | L14: 1107.5355 | M14: 6085.8626 | N14: 3042.9313 | O14: =(N14+L14)-(I14+J14+K14+M14) -> -3785.1337 | Q14: 2032 | R14: =SUM(I14,J14,K14,M14) -> 7935.6005 | S14: =SUM(L14,N14) -> 4150.4668 | T14: 7 | U14: =(W14+V14)*0.175 -> 43452.099 | V14: =R14-S14 -> 3785.1337 | W14: =F14-G14 -> 244512.58 | X14: =W14+V14-U14 -> 204845.61
A15: 2033 | B15: 36.164821 | C15: 28.22911 | D15: =(B15 -C15) -> 7.935711 | F15: =D15*$B$2*44/12 -> 261878.46 | G15: =SQRT('Sampling & Combined Error'!$E$14)*$B$2*44/12 -> 17330.613 | I15: 107.493 | J15: 187.7472 | K15: 1554.4977 | L15: 1107.5355 | M15: 6085.8626 | N15: 3042.9313 | O15: =(N15+L15)-(I15+J15+K15+M15) -> -3785.1337 | Q15: 2033 | R15: =SUM(I15,J15,K15,M15) -> 7935.6005 | S15: =SUM(L15,N15) -> 4150.4668 | T15: 8 | U15: =(W15+V15)*0.175 -> 43458.272 | V15: =R15-S15 -> 3785.1337 | W15: =F15-G15 -> 244547.85 | X15: =W15+V15-U15 -> 204874.71
A16: 2034 | B16: 36.164822 | C16: 28.228343 | D16: =(B16 -C16) -> 7.9364794 | F16: =D16*$B$2*44/12 -> 261903.82 | G16: =SQRT('Sampling & Combined Error'!$E$14)*$B$2*44/12 -> 17330.613 | I16: 107.493 | J16: 187.7472 | K16: 1554.4977 | L16: 1107.5355 | M16: 6085.8626 | N16: 3042.9313 | O16: =(N16+L16)-(I16+J16+K16+M16) -> -3785.1337 | Q16: 2034 | R16: =SUM(I16,J16,K16,M16) -> 7935.6005 | S16: =SUM(L16,N16) -> 4150.4668 | T16: 9 | U16: =(W16+V16)*0.175 -> 43462.71 | V16: =R16-S16 -> 3785.1337 | W16: =F16-G16 -> 244573.21 | X16: =W16+V16-U16 -> 204895.63
A17: 2035 | B17: 36.164823 | C17: 28.227789 | D17: =(B17 -C17) -> 7.9370336 | F17: =D17*$B$2*44/12 -> 261922.11 | G17: =SQRT('Sampling & Combined Error'!$E$14)*$B$2*44/12 -> 17330.613 | I17: 107.493 | J17: 187.7472 | K17: 1554.4977 | L17: 1107.5355 | M17: 6085.8626 | N17: 3042.9313 | O17: =(N17+L17)-(I17+J17+K17+M17) -> -3785.1337 | Q17: 2035 | R17: =SUM(I17,J17,K17,M17) -> 7935.6005 | S17: =SUM(L17,N17) -> 4150.4668 | T17: 10 | U17: =(W17+V17)*0.175 -> 43465.91 | V17: =R17-S17 -> 3785.1337 | W17: =F17-G17 -> 244591.49 | X17: =W17+V17-U17 -> 204910.72
A18: 2036 | B18: 36.164824 | C18: 28.227389 | D18: =(B18 -C18) -> 7.9374342 | F18: =D18*$B$2*44/12 -> 261935.33 | G18: =SQRT('Sampling & Combined Error'!$E$14)*$B$2*44/12 -> 17330.613 | I18: 107.493 | J18: 187.7472 | K18: 1554.4977 | L18: 1107.5355 | M18: 6085.8626 | N18: 3042.9313 | O18: =(N18+L18)-(I18+J18+K18+M18) -> -3785.1337 | Q18: 2036 | R18: =SUM(I18,J18,K18,M18) -> 7935.6005 | S18: =SUM(L18,N18) -> 4150.4668 | T18: 11 | U18: =(W18+V18)*0.175 -> 43468.224 | V18: =R18-S18 -> 3785.1337 | W18: =F18-G18 -> 244604.72 | X18: =W18+V18-U18 -> 204921.63
... A47: 2065 | B47: 36.164841 | C47: 28.226183 | D47: =(B47 -C47) -> 7.9386579 | F47: =D47*$B$2*44/12 -> 261975.71 | G47: =SQRT('Sampling & Combined Error'!$E$14)*$B$2*44/12 -> 17330.613 | I47: 107.493 | J47: 187.7472 | K47: 1554.4977 | L47: 1107.5355 | M47: 6085.8626 | N47: 3042.9313 | O47: =(N47+L47)-(I47+J47+K47+M47) -> -3785.1337 | Q47: 2065 | R47: =SUM(I47,J47,K47,M47) -> 7935.6005 | S47: =SUM(L47,N47) -> 4150.4668 | T47: 40 | U47: =(W47+V47)*0.175 -> 43475.29 | V47: =R47-S47 -> 3785.1337 | W47: =F47-G47 -> 244645.1 | X47: =W47+V47-U47 -> 204954.94

Sheet Baseline Model Error
A1: This sheet contains the calculations associated with the RothC model validation for the baseline scenario, and the associated calculation of model prediction error for the baseline.
A2: Baseline Literature Data by Sample | AG2: Calculations with RothC Baseline Model
A3: Full Citation | B3: Paper Name | C3: Sample ID | D3: Paper Type | E3: Location | F3: IPCC Climate Zone | G3: Latitude | H3: Longitude | I3: Practice Start Date | J3: Practice End Date | K3: Crop Functional Group (CFG) | L3: Duration of Practice (Years) | M3: Start Carbon (Original Unit) | N3: Start Carbon (Original Value) | O3: Start Carbon (SOC %) | P3: Start Carbon (tons/ha) | Q3: End Carbon (Original Unit) | R3: End Carbon (Original Value) | S3: End Carbon (SOC %) | T3: End Carbon (tons/ha) | U3: Sample Depth (m) | V3: Measurement Technique | W3: Start Bulk Density (g/cm3) | X3: End Bulk Density (g/cm3) | Y3: Bulk Density Source | Z3: Soil Type | AA3: USDA Soil Texture | AB3: Clay Content (%) | AC3: Clay Content Source | AD3: Practice / Treatment | AE3: Sample Standard Deviation (tons/ha) | AF3: Reported Number of Observations in This Sample | AG3: Carbon Change (tons/ha) | AH3: Carbon Change per Year (tons/ha/year) | AI3: Predicted End Carbon (tons/ha) | AJ3: Predicted Carbon Change (tons/ha) | AK3: Predicted Carbon Change per Year (tons/ha/year) | AL3: Predicted Carbon Change Error (tons/ha) | AM3: Predicted Carbon Change per Year Error (tons/ha/year) | AN3: Predicted Carbon Change per Year Error with mean removed (tons/ha/year)
A4: Hammad, H. M., Khaliq, A., Abbas, F., Farhad, W., Fahad, S., Aslam, M., ... & Bakhat, H. F. (2020). Comparative effects of organic and inorganic fertilizers on soil organic carbon and wheat productivity under arid region. Communications in Soil Science and Plant Analysis, 51(10), 1406-1422. | B4: Hammad et al. 2020 | C4: Hammad et al. 2020a | D4: Baseline Multiple | E4: Karor Lal Essan, Pakistan | F4: Warm Temperate Dry | G4: 31.215972 | H4: 70.969944 | I4: 38672 | J4: 39187 | K4: Wheat | L4: 2 | M4: OM % | N4: 0.48 | O4: =N4/1.724 -> 0.27842227 | P4: =10000*W4*U4*(O4/100) -> 12.445476 | Q4: % OM | R4: 0.46 | S4: =R4/1.724 -> 0.26682135 | T4: =10000*U4*X4*(S4/100) -> 11.206497 | U4: 0.3 | V4: Walkley Black | W4: 1.49 | X4: 1.4 | Y4: Paper-reported | AA4: Loam | AB4: 16 | AC4: Paper-reported | AD4: T2=recommended N, P2O5, and K2O at the rate of 150, 100, and 60 kg ha−1, respectively | AE4: 4.667 | AF4: 3 | AG4: =T4-P4 -> -1.2389791 | AH4: =AG4/L4 -> -0.61948956 | AI4: 12.002152 | AJ4: =AI4-P4 -> -0.44332342 | AK4: =AJ4/L4 -> -0.22166171 | AL4: =AJ4-AG4 -> 0.7956557 | AM4: =AK4-AH4 -> 0.39782785 | AN4: =AM4-AVERAGE($AM$4:$AM$16) -> 0.31709131
A5: Kawaka, F., Dida, M., Opala, P., Ombori, O., Maingi, J., Amoding, A., & Muoma, J. (2018). Effect of nitrogen sources on the yield of common bean (Phaseolus vulgaris) in western Kenya. Journal of Plant Nutrition, 41(13), 1652-1661. | B5: Kawaka et al. 2018 | C5: Kawaka et al. 2018a | D5: Baseline Multiple | E5: Kisumu, Kenya | F5: Tropical Montane | G5: -0.090792 | H5: 34.685281 | I5: 41334 | J5: 41517 | K5: Beans | L5: 1 | O5: 1.32 | P5: =10000*W5*U5*(O5/100) -> 34.2144 | S5: 1.325 | T5: =10000*U5*X5*(S5/100) -> 34.344 | U5: 0.2 | V5: unknown | W5: 1.296 | X5: 1.296 | Y5: Soilgrids | AA5: Clay | AB5: 66.88 | AC5: Paper-reported | AD5: Average of T4 and T16, Long rain | AE5: 2.3419377 | AF5: 2 | AG5: =T5-P5 -> 0.1296 | AH5: =AG5/L5 -> 0.1296 | AI5: 33.403199 | AJ5: =AI5-P5 -> -0.81120093 | AK5: =AJ5/L5 -> -0.81120093 | AL5: =AJ5-AG5 -> -0.94080093 | AM5: =AK5-AH5 -> -0.94080093 | AN5: =AM5-AVERAGE($AM$4:$AM$16) -> -1.0215375
A6: Kawaka, F., Dida, M., Opala, P., Ombori, O., Maingi, J., Amoding, A., & Muoma, J. (2018). Effect of nitrogen sources on the yield of common bean (Phaseolus vulgaris) in western Kenya. Journal of Plant Nutrition, 41(13), 1652-1661. | B6: Kawaka et al. 2018 | C6: Kawaka et al. 2018c | D6: Baseline Multiple | E6: Kakamega, Kenya | F6: Tropical Montane | G6: 0.281449 | H6: 34.767664 | I6: 41699 | J6: 41882 | K6: Beans | L6: 1 | O6: 2.66 | P6: =10000*W6*U6*(O6/100) -> 70.5432 | S6: 2.54 | T6: =10000*U6*X6*(S6/100) -> 67.3608 | U6: 0.2 | V6: unknown | W6: 1.326 | X6: 1.326 | Y6: Soilgrids | AA6: Clay | AB6: 18.16 | AC6: Paper-reported | AD6: Average of T4 and T16, Long rain | AE6: 2.3419377 | AF6: 2 | AG6: =T6-P6 -> -3.1824 | AH6: =AG6/L6 -> -3.1824 | AI6: 67.537859 | AJ6: =AI6-P6 -> -3.0053407 | AK6: =AJ6/L6 -> -3.0053407 | AL6: =AJ6-AG6 -> 0.17705926 | AM6: =AK6-AH6 -> 0.17705926 | AN6: =AM6-AVERAGE($AM$4:$AM$16) -> 0.096322726
A7: Kuttimani, R., Somasundaram, E. , & Velayudham, K. (2017). Ecofriendly nutrient management practices for yield and soil organic of banana. Internaitonal Journal of Applid and Natural Sciences, 6, 55-60 | B7: Kuttamani and Velayudham 2017 | C7: Kuttamani and Velayudham 2017a | D7: Baseline Multiple | E7: Tamil Nadu, India | F7: Tropical Dry | G7: 11.482675 | H7: 77.136518 | I7: 40299 | J7: 40663 | K7: Banana | L7: 1 | O7: 0.51 | P7: =10000*W7*U7*(O7/100) -> 13.77 | S7: 0.5 | T7: =10000*U7*X7*(S7/100) -> 12.8 | U7: 0.2 | V7: unknown | W7: 1.35 | X7: 1.28 | Y7: Paper-reported | AA7: Clay Loam | AB7: 35.705 | AC7: Soilgrids | AD7: T1 - 100% RDF (Control) | AE7: 4.667 | AF7: 1 | AG7: =T7-P7 -> -0.97 | AH7: =AG7/L7 -> -0.97 | AI7: 13.04231 | AJ7: =AI7-P7 -> -0.72769019 | AK7: =AJ7/L7 -> -0.72769019 | AL7: =AJ7-AG7 -> 0.24230981 | AM7: =AK7-AH7 -> 0.24230981 | AN7: =AM7-AVERAGE($AM$4:$AM$16) -> 0.16157327
A8: Luo, C. L., Zhang, X. F., Duan, H. X., Mburu, D. M., Ren, H. X., Kavagi, L., ... & Xiong, Y. C. (2020). Dual plastic film and straw mulching boosts wheat productivity and soil quality under the El Nino in semiarid Kenya. Science of the Total Environment, 738, 139808. | B8: Luo et al. 2020 | C8: Luo et al. 2020a | D8: Baseline Multiple | E8: Juja, Kenya | F8: Tropical Montane | G8: -1.089111 | H8: 37.009778 | I8: 42309 | J8: 42917 | K8: Wheat | L8: 2 | M8: g/kg | N8: 14.45 | O8: =N8/10 -> 1.445 | P8: =10000*W8*U8*(O8/100) -> 62.8575 | Q8: g/kg | R8: 14 | S8: =R8/10 -> 1.4 | T8: =10000*U8*X8*(S8/100) -> 61.95 | U8: 0.3 | V8: Walkley Black | W8: 1.45 | X8: 1.475 | Y8: Paper-reported | AA8: Clay | AB8: 58.3 | AC8: Paper-reported | AD8: T6 = No mulching in RF was used as the control group (CK) + 100% NPK | AE8: 4.667 | AF8: 1 | AG8: =T8-P8 -> -0.9075 | AH8: =AG8/L8 -> -0.45375 | AI8: 62.439633 | AJ8: =AI8-P8 -> -0.41786704 | AK8: =AJ8/L8 -> -0.20893352 | AL8: =AJ8-AG8 -> 0.48963296 | AM8: =AK8-AH8 -> 0.24481648 | AN8: =AM8-AVERAGE($AM$4:$AM$16) -> 0.16407994
A9: Mishra, G., & Kushwaha, H. S. (2016). Winter wheat yield and soil physical properties responses to different tillage and irrigation.√äEuropean Journal of Biological Research,√ä6(1), 56-63. | B9: Mishra and Kushwaha 2016 | C9: Mishra and Kushwaha 2016a | D9: Baseline Multiple | E9: Ratna Chunni Lal, Uttar Pradesh, India | F9: Tropical Dry | G9: 28.5 | H9: 79.5 | I9: 40817 | J9: 41365 | K9: Wheat | L9: 2 | O9: 0.73 | P9: =10000*W9*U9*(O9/100) -> 15.4395 | S9: 0.76 | T9: =10000*U9*X9*(S9/100) -> 15.504 | U9: 0.15 | V9: Dry Combustion | W9: 1.41 | X9: 1.36 | Y9: Paper-reported | Z9: Cambisols | AA9: Clay Loam | AB9: 28.444444 | AC9: Soilgrids | AD9: T2: (CT) Conventional Tillage | AE9: 4.667 | AF9: 1 | AG9: =T9-P9 -> 0.0645 | AH9: =AG9/L9 -> 0.03225 | AI9: 14.351521 | AJ9: =AI9-P9 -> -1.0879789 | AK9: =AJ9/L9 -> -0.54398943 | AL9: =AJ9-AG9 -> -1.1524789 | AM9: =AK9-AH9 -> -0.57623943 | AN9: =AM9-AVERAGE($AM$4:$AM$16) -> -0.65697597
A10: Novara, A., Poma, I., Sarno, M., Venezia, G., & Gristina, L. (2016). Long‚Äêterm durum wheat‚Äêbased cropping systems result in the rapid saturation of soil carbon in the Mediterranean semi‚Äêarid environment. Land degradation & development, 27(3), 612-619. | B10: Novara et al. 2016 | C10: Novara et al. 2016a | D10: Baseline Multiple | E10: Cammarata, AG, Italy | F10: Warm Temperate Dry | G10: 37.627827 | H10: 13.715096 | I10: 35796 | J10: 40330 | K10: Wheat | L10: 12 | M10: g/kg | N10: 16.4 | O10: =N10/10 -> 1.64 | P10: =10000*W10*U10*(O10/100) -> 71.7336 | Q10: g/kg | R10: 16.14 | S10: =R10/10 -> 1.614 | T10: =10000*U10*X10*(S10/100) -> 70.59636 | U10: 0.3 | V10: Walkley Black | W10: 1.458 | X10: 1.458 | Y10: Soilgrids | AA10: Clay Loam | AB10: 57.7 | AC10: Paper-reported | AD10: T4 = Wfall = durum wheat/fallow without return of aboveground residues to the soil. | AE10: 4.667 | AF10: 1 | AG10: =T10-P10 -> -1.13724 | AH10: =AG10/L10 -> -0.09477 | AI10: 69.952499 | AJ10: =AI10-P10 -> -1.7811008 | AK10: =AJ10/L10 -> -0.14842507 | AL10: =AJ10-AG10 -> -0.64386081 | AM10: =AK10-AH10 -> -0.053655067 | AN10: =AM10-AVERAGE($AM$4:$AM$16) -> -0.1343916
A11: Nyamadzawo, G., Chikowo, R., Nyamugafata, P., Nyamangara, J., & Giller, K. E. (2008). Soil organic carbon dynamics of improved fallow-maize rotation systems under conventional and no-tillage in Central Zimbabwe. Nutrient Cycling in Agroecosystems, 81, 85-93. | B11: Nyamadzawo et al. 2008 | C11: Nyamadzawo et al. 2008a | D11: Baseline Multiple | E11: Domboshawa, Zimbabwe | F11: Tropical Montane | G11: -19.583 | H11: 31.233 | I11: 36800 | J11: 37530 | K11: Maize | L11: 2 | P11: 16.9 | T11: 16.8 | U11: 0.2 | V11: Walkley Black | W11: 1.4 | X11: 1.43 | Y11: Paper-reported | AA11: Sandy Clay Loam | AB11: 22 | AC11: Paper-reported | AD11: CT (conventional tillage) and CM (continuous maize) | AE11: 4.667 | AF11: 3 | AG11: =T11-P11 -> -0.1 | AH11: =AG11/L11 -> -0.05 | AI11: 16.534385 | AJ11: =AI11-P11 -> -0.36561489 | AK11: =AJ11/L11 -> -0.18280745 | AL11: =AJ11-AG11 -> -0.26561489 | AM11: =AK11-AH11 -> -0.13280745 | AN11: =AM11-AVERAGE($AM$4:$AM$16) -> -0.21354398
A12: Patil, S. B., BC, B. R., Chitgupekar, S. C., & Patil, B. B. (2015). Modern tillage and integrated nutrient management practices for improving soil fertility and productivity of groundnut (Arachis hypogaea L.) under rainfed farming system. International Letters of Natural Sciences, (02). | B12: Patil et al. 2015 | C12: Patil et al. 2015a | D12: Baseline Multiple | E12: Bengaluru, Karnataka, India | F12: Tropical Dry | G12: 13.0785 | H12: 77.570116 | I12: 39288 | J12: 39387 | K12: Beans | L12: 1 | O12: 0.56 | P12: =10000*W12*U12*(O12/100) -> 11.4912 | S12: 0.54 | T12: =10000*U12*X12*(S12/100) -> 11.0808 | U12: 0.15 | V12: Walkley Black | W12: 1.368 | X12: 1.368 | Y12: Soilgrids | AA12: Sandy Clay Loam | AB12: 17.4 | AC12: Paper-reported | AD12: T2F2= Conventional tillage + two intercultivations, 100% NPK | AE12: 4.667 | AF12: 1 | AG12: =T12-P12 -> -0.4104 | AH12: =AG12/L12 -> -0.4104 | AI12: 11.300998 | AJ12: =AI12-P12 -> -0.19020236 | AK12: =AJ12/L12 -> -0.19020236 | AL12: =AJ12-AG12 -> 0.22019764 | AM12: =AK12-AH12 -> 0.22019764 | AN12: =AM12-AVERAGE($AM$4:$AM$16) -> 0.13946111
A13: Suner, L., Galantini, J., & Minoldo, G. (2014). Soil phosphorus dynamics of wheat-based cropping systems in the semiarid region of Argentina. Applied and Environmental Soil Science, 2014. | B13: Suner et al. 2014 | C13: Suner et al. 2014a | D13: Baseline Multiple | E13: Bordenave, Buenos Aires Province, Argentina | F13: Warm Temperate Dry | G13: -37.8653 | H13: -63.0222 | I13: 30437 | J13: 35034 | K13: Wheat | L13: 12 | O13: 1.28 | P13: =10000*W13*U13*(O13/100) -> 26.496 | S13: 0.95 | T13: =10000*U13*X13*(S13/100) -> 19.665 | U13: 0.15 | V13: Dry Combustion | W13: 1.38 | X13: 1.38 | Y13: Soilgrids | AA13: Clay Loam | AB13: 10.1 | AC13: Paper-reported | AD13: T2: WW, continuous wheat. Following harvest, there was a 4–6-month fallow (January–June) under stubble mulch used for soil moisture storage, mechanical weed control using chisel ploughing to a depth of 0.20 m preceded wheat deep-furrow seeding, which deposits the seed 8–10 cm deep. | AE13: 4.667 | AF13: 1 | AG13: =T13-P13 -> -6.831 | AH13: =AG13/L13 -> -0.56925 | AI13: 25.767992 | AJ13: =AI13-P13 -> -0.72800801 | AK13: =AJ13/L13 -> -0.060667334 | AL13: =AJ13-AG13 -> 6.102992 | AM13: =AK13-AH13 -> 0.50858267 | AN13: =AM13-AVERAGE($AM$4:$AM$16) -> 0.42784613
A14: Swanepoel, C. M., R√∂tter, R. P., Van der Laan, M., Annandale, J. G., Beukes, D. J., du Preez, C. C., ... & Hoffmann, M. P. (2018). The benefits of conservation agriculture on soil organic carbon and yield in southern Africa are site-specific. Soil and Tillage Research, 183, 72-82. | B14: Swanepoel et al. 2018 | C14: Swanepoel et al. 2018a | D14: Baseline Multiple | E14: Buffelsvallei, South Africa | F14: Warm Temperate Dry | G14: -26.495 | H14: 26.601944 | I14: 39753 | J14: 41759 | K14: Maize | L14: 6 | O14: 0.43 | P14: =10000*W14*U14*(O14/100) -> 20.64 | S14: 0.34 | T14: =10000*U14*X14*(S14/100) -> 16.32 | U14: 0.3 | V14: Walkley Black | W14: 1.6 | X14: 1.6 | Y14: Paper-reported | AA14: Sandy Clay Loam | AB14: 16 | AC14: Paper-reported | AD14: a: maize monoculture, conventional tillage | AE14: 4.667 | AF14: 3 | AG14: =T14-P14 -> -4.32 | AH14: =AG14/L14 -> -0.72 | AI14: 20.058084 | AJ14: =AI14-P14 -> -0.58191555 | AK14: =AJ14/L14 -> -0.096985925 | AL14: =AJ14-AG14 -> 3.7380845 | AM14: =AK14-AH14 -> 0.62301408 | AN14: =AM14-AVERAGE($AM$4:$AM$16) -> 0.54227754
A15: Swanepoel, C. M., R√∂tter, R. P., Van der Laan, M., Annandale, J. G., Beukes, D. J., du Preez, C. C., ... & Hoffmann, M. P. (2018). The benefits of conservation agriculture on soil organic carbon and yield in southern Africa are site-specific. Soil and Tillage Research, 183, 72-82. | B15: Swanepoel et al. 2018 | C15: Swanepoel et al. 2018b | D15: Baseline Multiple | E15: Zeekoegat, South Africa | F15: Warm temperate Dry | G15: -25.615278 | H15: 28.315556 | I15: 39753 | J15: 41394 | K15: Maize | L15: 5 | O15: 1.24 | P15: =10000*W15*U15*(O15/100) -> 53.94 | S15: 1.225 | T15: =10000*U15*X15*(S15/100) -> 53.2875 | U15: 0.3 | V15: Walkley Black | W15: 1.45 | X15: 1.45 | Y15: Paper-reported | AA15: Sandy Clay Loam | AB15: 44.5 | AC15: Paper-reported | AD15: a: maize monoculture, conventional tillage | AE15: 4.667 | AF15: 3 | AG15: =T15-P15 -> -0.6525 | AH15: =AG15/L15 -> -0.1305 | AI15: 53.346019 | AJ15: =AI15-P15 -> -0.59398086 | AK15: =AJ15/L15 -> -0.11879617 | AL15: =AJ15-AG15 -> 0.058519142 | AM15: =AK15-AH15 -> 0.011703828 | AN15: =AM15-AVERAGE($AM$4:$AM$16) -> -0.069032708
A16: Wu, Z., Tang, Z., Yu, T., Zhang, J., Zheng, Y., Yang, J., ... & Sun, Q. (2023). Nitrogen fertilization rates mediate rhizosphere soil carbon emissions of continuous peanut monoculture by altering cellulose-specific microbess. Frontiers in Plant Science, 14, 1109860. | B16: Wu et al. 2023 | C16: Wu et al. 2023a | D16: Baseline Multiple | E16: Laixi, Qingdao, Shandong, China | F16: Warm Temperate Dry | G16: 36.81306 | H16: 120.50472 | I16: 42856 | J16: 44378 | K16: Beans | L16: 4 | M16: OM g/kg | N16: 11.9 | O16: =(N16/1.724)/10 -> 0.69025522 | P16: =10000*W16*U16*(O16/100) -> 28.638689 | Q16: g/kg | R16: 6.47 | S16: =R16/10 -> 0.647 | T16: =10000*U16*X16*(S16/100) -> 26.84403 | U16: 0.3 | V16: Walkley Black | W16: 1.383 | X16: 1.383 | Y16: Soilgrids | AA16: Loam | AB16: 18.869767 | AC16: Soilgrids | AD16: 100% recommended N rate (N120) | AE16: 4.667 | AF16: 1 | AG16: =T16-P16 -> -1.7946591 | AH16: =AG16/L16 -> -0.44866477 | AI16: 28.154295 | AJ16: =AI16-P16 -> -0.48439414 | AK16: =AJ16/L16 -> -0.12109853 | AL16: =AJ16-AG16 -> 1.310265 | AM16: =AK16-AH16 -> 0.32756624 | AN16: =AM16-AVERAGE($AM$4:$AM$16) -> 0.2468297
A19: Data by Journal Article
A20: Paper Name | B20: Number of Samples | C20: Climate Zone | D20: Carbon Change Standard Deviation (tons/ha) | E20: Duration of Practice (Average if Multiple Trials) | F20: Yearly Carbon Change Standard Deviation (tons/ha/year)
A21: Hammad et al. 2020 | B21: 3 | C21: Warm Temperate Dry | D21: 4.667 | E21: =L4 -> 2 | F21: =D21/E21 -> 2.3335
A22: Kawaka et al. 2018 | B22: 4 | C22: Tropical Montane | D22: 2.3419377 | E22: =AVERAGE(L5:L6) -> 1 | F22: =SQRT(AVERAGE(((AE5/L5)^2),((AE6/L6)^2))) -> 2.3419377
A23: Kuttamani and Velayudham 2017 | B23: 1 | C23: Tropical Dry | D23: 4.667 | E23: =L7 -> 1 | F23: =D23/E23 -> 4.667
A24: Luo et al. 2020 | B24: 1 | C24: Tropical Montane | D24: 4.667 | E24: =L8 -> 2 | F24: =D24/E24 -> 2.3335
A25: Mishra and Kushwaha 2016 | B25: 1 | C25: Tropical Dry | D25: 4.667 | E25: =L9 -> 2 | F25: =D25/E25 -> 2.3335
A26: Novara et al. 2016 | B26: 1 | C26: Warm Temperate Dry | D26: 4.667 | E26: =L10 -> 12 | F26: =D26/E26 -> 0.38891667
A27: Nyamadzawo et al. 2008 | B27: 3 | C27: Tropical Montane | D27: 4.667 | E27: =L11 -> 2 | F27: =D27/E27 -> 2.3335
A28: Patil et al. 2015 | B28: 1 | C28: Tropical Dry | D28: 4.667 | E28: =L12 -> 1 | F28: =D28/E28 -> 4.667
A29: Suner et al. 2014 | B29: 1 | C29: Warm Temperate Dry | D29: 4.667 | E29: =L13 -> 12 | F29: =D29/E29 -> 0.38891667
A30: Swanepoel et al. 2018 | B30: 6 | C30: Warm Temperate Dry | D30: 4.667 | E30: =AVERAGE(L14:L15) -> 5.5 | F30: =SQRT(AVERAGE(((AE14/L14)^2),((AE15/L15)^2))) -> 0.859145
A31: Wu et al. 2023 | B31: 1 | C31: Warm Temperate Dry | D31: 4.667 | E31: =L16 -> 4 | F31: =D31/E31 -> 1.16675
A34: Pooled Measurement Uncertainty
A35: Yearly Pooled Measurement Uncertainty (tons/ha/year)
A36: {=SQRT(SUM((F21:F31)^2 *( B21:B31 -1)) / (SUM(B21:B31 -1)))} -> 1.86917
A40: Pooled Measurement Uncertainty Comparison: Bias of each paper must be less than the PMU
A41: Paper Name | B41: Yearly Carbon Change Bias (tons/ha/year) | C41: Pass/Fail PMU Test (Yearly Carbon Change)
A42: Hammad et al. 2020 | B42: =AVERAGE(AM4) -> 0.39782785 | C42: =IF(ABS(B42)<$A$36, "PASS", "FAIL") -> PASS
A43: Kawaka et al. 2018 | B43: =AVERAGE(AM5:AM6) -> -0.38187083 | C43: =IF(ABS(B43)<$A$36, "PASS", "FAIL") -> PASS
A44: Kuttamani and Velayudham 2017 | B44: =AVERAGE(AM7) -> 0.24230981 | C44: =IF(ABS(B44)<$A$36, "PASS", "FAIL") -> PASS
A45: Luo et al. 2020 | B45: =AVERAGE(AM8) -> 0.24481648 | C45: =IF(ABS(B45)<$A$36, "PASS", "FAIL") -> PASS
A46: Mishra and Kushwaha 2016 | B46: =AVERAGE(AM9) -> -0.57623943 | C46: =IF(ABS(B46)<$A$36, "PASS", "FAIL") -> PASS
A47: Novara et al. 2016 | B47: =AVERAGE(AM10) -> -0.053655067 | C47: =IF(ABS(B47)<$A$36, "PASS", "FAIL") -> PASS
...

Sheet Project Model Error
A1: This sheet contains the calculations associated with the RothC model validation for the project scenario, and the associated calculation of model prediction error for the project scenario
A2: Improved Practice Literature Data by Sample | AG2: Calculations with RothC Project Model
A3: Full Citation | B3: Paper Name | C3: Sample ID | D3: Paper Type | E3: Location | F3: IPCC Climate Zone | G3: Latitude | H3: Longitude | I3: Practice Start Date | J3: Practice End Date | K3: Crop Functional Group (CFG) | L3: Duration of Practice (Years) | M3: Start Carbon (Original Unit) | N3: Start Carbon (Original Value) | O3: Start Carbon (SOC %) | P3: Start Carbon (tons/ha) | Q3: End Carbon (Original Unit) | R3: End Carbon (Original Value) | S3: End Carbon (SOC %) | T3: End Carbon (tons/ha) | U3: Sample Depth (m) | V3: Measurement Technique | W3: Start Bulk Density (g/cm3) | X3: End Bulk Density (g/cm3) | Y3: Bulk Density Source | Z3: Soil Type | AA3: USDA Soil Texture | AB3: Clay Content (%) | AC3: Clay Content Source | AD3: Practice / Treatment | AE3: Sample Standard Deviation (tons/ha) | AF3: Reported Number of Observations in This Sample | AG3: Carbon Change (tons/ha) | AH3: Carbon Change per Year (tons/ha/year) | AI3: Predicted End Carbon (tons/ha) | AJ3: Predicted Carbon Change (tons/ha) | AK3: Predicted Carbon Change per Year (tons/ha/year) | AL3: Predicted Carbon Change Error (tons/ha) | AM3: Predicted Carbon Change per Year Error (tons/ha/year) | AN3: Predicted Carbon Change per Year Error with mean removed (tons/ha/year)
A4: Babu, M. V., Nataraja, K. C., Srihari, A., Reddy, B. S., Ravindrachary, G., & Rao, C. S. (2016). Impact of Long Term Integrated Nutrient Management on Groundnut Yield and Soil Properties in Scarce Rainfall Zone of Andhra Pradesh, India. Indian Journal of Ecology, 43(Special Issue 1), 452-454. | B4: Babu et al. 2016 | C4: Babu et al. 2016b | D4: Improved Multiple | E4: Chennarayunipalle, Andhra Pradesh, India | F4: Tropical Dry | G4: 14.7 | H4: 77.6667 | I4: 31199 | J4: 41578 | K4: Beans | L4: 28 | O4: 0.3 | P4: =10000*W4*U4*(O4/100) -> 9.18 | S4: 0.55 | T4: =10000*X4*U4*(S4/100) -> 16.28 | U4: 0.2 | V4: Walkley Black | W4: 1.53 | X4: 1.48 | Y4: Paper-reported | Z4: Vertisols | AA4: Clay Loam | AB4: 37.115926 | AC4: Soilgrids | AD4: T7 = Half RFD (T3) +FYM @ 4 t/ha (T5) | AE4: 4.667 | AF4: 1 | AG4: =T4-P4 -> 7.1 | AH4: =AG4/L4 -> 0.25357143 | AI4: 16.28 | AJ4: =AI4-P4 -> 7.1 | AK4: =AJ4/L4 -> 0.25357143 | AL4: =AJ4-AG4 -> 8.9883656e-13 | AM4: =AK4-AH4 -> 3.2085445e-14 | AN4: =AM4-AVERAGE($AM$4:$AM$19) -> 5.5748808e-14
A5: Bhalerao, V. P., Patil, N. M., Badgujar, C. D., & Patil, D. R. (2009). Studies on integrated nutrient management for tissue cultured Grand Naine banana. Indian Journal of Agricultural Research, 43(2), 107-112. | B5: Bhalerao et al. 2009 | C5: Bhalerao et al. 2009 | D5: Improved Multiple | E5: Jalgaon, Maharashtra, India | F5: Tropical Dry | G5: 21.024895 | H5: 75.53185 | I5: 37408 | J5: 38473 | K5: Banana | L5: 3 | O5: 0.28 | P5: =10000*W5*U5*(O5/100) -> 13.3224 | S5: 0.49 | T5: =10000*X5*U5*(S5/100) -> 23.3142 | U5: 0.3 | V5: Walkley and Black | W5: 1.586 | X5: 1.586 | Y5: Soilgrids | Z5: unknown | AA5: Clay Loam | AB5: 38.189844 | AC5: Soilgrids | AD5: T3 vs T1 (control) using a space-for-time | AE5: 4.667 | AF5: 1 | AG5: =T5-P5 -> 9.9918 | AH5: =AG5/L5 -> 3.3306 | AI5: 23.3142 | AJ5: =AI5-P5 -> 9.9918 | AK5: =AJ5/L5 -> 3.3306 | AL5: =AJ5-AG5 -> 0 | AM5: =AK5-AH5 -> 0 | AN5: =AM5-AVERAGE($AM$4:$AM$19) -> 2.3663363e-14
A6: Abd El-Azeim, M. M., Sherif, M. A., Hussien, M. S., & Haddad, S. A. (2020). Temporal impacts of different fertilization systems on soil health under arid conditions of potato monocropping. Journal of Soil Science and Plant Nutrition, 20, 322-334. | B6: El-Azeim et al. 2020 | C6: El-Azeim et al. 2020 | D6: Improved Multiple | E6: Minya, Egypt | F6: Warm Temperate Dry | G6: 28.3044 | H6: 30.5772 | I6: 43101 | J6: 43235 | K6: Wheat | L6: 1 | M6: g/kg | N6: 18.48 | O6: =N6/10 -> 1.848 | P6: =10000*W6*U6*(O6/100) -> 48.4176 | Q6: g/kg | R6: 23.4 | S6: =R6/10 -> 2.34 | T6: =10000*X6*U6*(S6/100) -> 63.6948 | U6: 0.2 | V6: Walkley and Black | W6: 1.31 | X6: 1.361 | Y6: Paper-reported | Z6: unknown | AA6: Sandy Clay Loam | AB6: 56.45 | AC6: Paper-reported | AD6: Control was compost only, NPK was used for chemical fertizlizers, nanofertilizers. There are also compost = (100%, 50%, or 25%) synthetic fertilizers. In trials with compost, 40 t/ha were applied. Interested in Control, FS5, FS6, FS7, FS8. No dates are provided, not even a year, all we know is that harvest was 115 days after planting. No sample depth is provided. | AE6: 4.667 | AF6: 1 | AG6: =T6-P6 -> 15.2772 | AH6: =AG6/L6 -> 15.2772 | AI6: 63.6948 | AJ6: =AI6-P6 -> 15.2772 | AK6: =AJ6/L6 -> 15.2772 | AL6: =AJ6-AG6 -> 0 | AM6: =AK6-AH6 -> 0 | AN6: =AM6-AVERAGE($AM$4:$AM$19) -> 2.3663363e-14
A7: Guo, Yifan, Mingyou Chen, Junxiao Pan, Yiwei Shang, Xingjie Wu, and Zhenling Cui. "Increasing soil organic carbon sequestration while closing the yield gap in Chinese wheat production."¬†Land Degradation & Development¬†32, no. 3 (2021): 1274-1286. | B7: Guo et al. 2020 | C7: Guo et al. 2020 | D7: Improved Multiple | E7: Quzhou County, Handan, Hebei, China | F7: Warm Temperate Dry | G7: 36.9 | H7: 115 | I7: 41183 | J7: 43617 | K7: Wheat | L7: 7 | P7: 36.5 | T7: 51.9 | U7: 0.2 | V7: Dry Combustion | W7: 1.37 | X7: 1.37 | Y7: Soilgrids | Z7: Phaeozems | AA7: Loam | AB7: 20.464583 | AC7: Soilgrids | AD7: Improved crop management combined with manure application (IMsoil) | AE7: 4.667 | AF7: 1 | AG7: =T7-P7 -> 15.4 | AH7: =AG7/L7 -> 2.2 | AI7: 51.9 | AJ7: =AI7-P7 -> 15.4 | AK7: =AJ7/L7 -> 2.2 | AL7: =AJ7-AG7 -> -3.9790393e-13 | AM7: =AK7-AH7 -> -5.6843419e-14 | AN7: =AM7-AVERAGE($AM$4:$AM$19) -> -3.3180056e-14
A8: Hammad, H. M., Khaliq, A., Abbas, F., Farhad, W., Fahad, S., Aslam, M., ... & Bakhat, H. F. (2020). Comparative effects of organic and inorganic fertilizers on soil organic carbon and wheat productivity under arid region. Communications in Soil Science and Plant Analysis, 51(10), 1406-1422. | B8: Hammad et al. 2020 | C8: Hammad et al. 2020b | D8: Improved Multiple | E8: Karor Lal Essan, Pakistan | F8: Warm Temperate Dry | G8: 31.215972 | H8: 70.969944 | I8: 38672 | J8: 39187 | K8: Wheat | L8: 2 | M8: OM (%) | N8: 0.48 | O8: =N8/1.72 -> 0.27906977 | P8: =10000*W8*U8*(O8/100) -> 11.469767 | Q8: OM (%) | R8: 0.57 | S8: =R8/1.72 -> 0.33139535 | T8: =10000*X8*U8*(S8/100) -> 11.631977 | U8: 0.3 | V8: Walkley and Black | W8: 1.37 | X8: 1.17 | Y8: Paper-reported | Z8: unknown | AA8: Loam | AB8: 16 | AC8: Paper-reported | AD8: T3 = (FM + PL) | AE8: 4.667 | AF8: 3 | AG8: =T8-P8 -> 0.1622093 | AH8: =AG8/L8 -> 0.081104651 | AI8: 11.631977 | AJ8: =AI8-P8 -> 0.1622093 | AK8: =AJ8/L8 -> 0.081104651 | AL8: =AJ8-AG8 -> -4.6185278e-14 | AM8: =AK8-AH8 -> -2.3092639e-14 | AN8: =AM8-AVERAGE($AM$4:$AM$19) -> 5.7072402e-16
A9: Kuttimani, R., Somasundaram, E. , & Velayudham, K. (2017). Ecofriendly nutrient management practices for yield and soil organic of banana. Internaitonal Journal of Applid and Natural Sciences, 6, 55-60 | B9: Kuttamani and Velayudham 2017 | C9: Kuttamani and Velayudham 2017b | D9: Improved Multiple | E9: Tamil Nadu, India | F9: Tropical Dry | G9: 11.482675 | H9: 77.136518 | I9: 40299 | J9: 41029 | K9: Banana | L9: 2 | O9: 0.51 | P9: =10000*W9*U9*(O9/100) -> 13.77 | S9: 0.943 | T9: =10000*X9*U9*(S9/100) -> 25.461 | U9: 0.2 | V9: Walkley Black | W9: 1.35 | X9: 1.35 | Y9: Paper-reported | Z9: Vertisols | AA9: Clay Loam | AB9: 35.705 | AC9: Soilgrids | AD9: T13 = 75% RDF + FYM | AE9: 4.667 | AF9: 1 | AG9: =T9-P9 -> 11.691 | AH9: =AG9/L9 -> 5.8455 | AI9: 25.461 | AJ9: =AI9-P9 -> 11.691 | AK9: =AJ9/L9 -> 5.8455 | AL9: =AJ9-AG9 -> -9.9475983e-14 | AM9: =AK9-AH9 -> -4.9737992e-14 | AN9: =AM9-AVERAGE($AM$4:$AM$19) -> -2.6074629e-14
A10: Luo, C. L., Zhang, X. F., Duan, H. X., Mburu, D. M., Ren, H. X., Kavagi, L., ... & Xiong, Y. C. (2020). Dual plastic film and straw mulching boosts wheat productivity and soil quality under the El Nino in semiarid Kenya. Science of the Total Environment, 738, 139808. | B10: Luo et al. 2020b | C10: Luo et al. 2020b | D10: Improved Multiple | E10: Juja, Kenya | F10: Tropical Montane | G10: -1.086158 | H10: 37.007671 | I10: 42309 | J10: 42917 | K10: Wheat | L10: 2 | M10: g/kg | N10: 14.45 | O10: =N10/10 -> 1.445 | P10: =10000*W10*U10*(O10/100) -> 62.8575 | Q10: g/kg | R10: 15.6 | S10: =R10/10 -> 1.56 | T10: =10000*X10*U10*(S10/100) -> 65.52 | U10: 0.3 | V10: Walkley and Black | W10: 1.45 | X10: 1.4 | Y10: Paper-reported | Z10: unknown | AA10: Clay | AB10: 58.3 | AC10: Paper-reported | AD10: T1 = furrows mulched with wheat straw and ridges mulched with black plastic film (Rfbs) + 100% NPK | AE10: 4.667 | AF10: 1 | AG10: =T10-P10 -> 2.6625 | AH10: =AG10/L10 -> 1.33125 | AI10: 65.52 | AJ10: =AI10-P10 -> 2.6625 | AK10: =AJ10/L10 -> 1.33125 | AL10: =AJ10-AG10 -> -1.1368684e-13 | AM10: =AK10-AH10 -> -5.6843419e-14 | AN10: =AM10-AVERAGE($AM$4:$AM$19) -> -3.3180056e-14
A11: Mishra, G., & Kushwaha, H. S. (2016). Winter wheat yield and soil physical properties responses to different tillage and irrigation.¬†European Journal of Biological Research,¬†6(1), 56-63. | B11: Mishra and Kushwaha 2016 | C11: Mishra and Kushwaha 2016b | D11: Improved Multiple | E11: Ratna Chunni Lal, Uttar Pradesh, India | F11: Tropical Dry | G11: 28.5 | H11: 79.5 | I11: 40817 | J11: 41365 | K11: Wheat | L11: 2 | O11: 0.73 | P11: =10000*W11*U11*(O11/100) -> 15.4395 | S11: 0.76 | T11: =10000*X11*U11*(S11/100) -> 16.302 | U11: 0.15 | V11: Dry Combustion | W11: 1.41 | X11: 1.43 | Y11: Paper-reported | Z11: Cambisols | AA11: Clay Loam | AB11: 28.444444 | AC11: Soilgrids | AD11: T1=(ZT) zero tillage | AE11: 4.667 | AF11: 1 | AG11: =T11-P11 -> 0.8625 | AH11: =AG11/L11 -> 0.43125 | AI11: 16.302 | AJ11: =AI11-P11 -> 0.8625 | AK11: =AJ11/L11 -> 0.43125 | AL11: =AJ11-AG11 -> 0 | AM11: =AK11-AH11 -> 0 | AN11: =AM11-AVERAGE($AM$4:$AM$19) -> 2.3663363e-14
A12: Nyamadzawo, G., Chikowo, R., Nyamugafata, P., Nyamangara, J., & Giller, K. E. (2008). Soil organic carbon dynamics of improved fallow-maize rotation systems under conventional and no-tillage in Central Zimbabwe. Nutrient Cycling in Agroecosystems, 81, 85-93. | B12: Nyamadzawo et al. 2008 | C12: Nyamadzawo et al. 2008b | D12: Improved Multiple | E12: Domboshawa, Zimbabwe | F12: Tropical Montane | G12: -17.607843 | H12: 31.140328 | I12: 36831 | J12: 37376 | K12: Maize | L12: 2 | P12: 6.32 | T12: 6.35 | U12: 0.2 | V12: Walkley and Black | W12: 1.533 | X12: 1.533 | Y12: Soilgrids | Z12: unknown | AA12: Sandy Clay Loam | AB12: 22 | AC12: Paper-reported | AE12: 4.667 | AF12: 1 | AG12: =T12-P12 -> 0.03 | AH12: =AG12/L12 -> 0.015 | AI12: 6.35 | AJ12: =AI12-P12 -> 0.03 | AK12: =AJ12/L12 -> 0.015 | AL12: =AJ12-AG12 -> -4.9737992e-14 | AM12: =AK12-AH12 -> -2.4868996e-14 | AN12: =AM12-AVERAGE($AM$4:$AM$19) -> -1.2056328e-15
A13: Patil, S. B., BC, B. R., Chitgupekar, S. C., & Patil, B. B. (2015). Modern tillage and integrated nutrient management practices for improving soil fertility and productivity of groundnut (Arachis hypogaea L.) under rainfed farming system. International Letters of Natural Sciences, (02). | B13: Patil et al. 2015b | C13: Patil et al. 2015b | D13: Improved Multiple | E13: Bengaluru, Karnataka, IND | F13: Tropical Dry | G13: 13.0785 | H13: 77.570116 | I13: 39288 | J13: 39387 | K13: Beans | L13: 1 | O13: 0.56 | P13: =10000*W13*U13*(O13/100) -> 11.4912 | S13: 0.67 | T13: =10000*X13*U13*(S13/100) -> 13.7484 | U13: 0.15 | V13: Walkley and Black | W13: 1.368 | X13: 1.368 | Y13: Soilgrids | Z13: unknown | AA13: Sandy Clay Loam | AB13: 17.4 | AC13: Paper-reported | AD13: T1F1= Conventional tillage + one intercultivation, 100% organics (FYM @ 25 kg N equivalent) | AE13: 4.667 | AF13: 1 | AG13: =T13-P13 -> 2.2572 | AH13: =AG13/L13 -> 2.2572 | AI13: 13.7484 | AJ13: =AI13-P13 -> 2.2572 | AK13: =AJ13/L13 -> 2.2572 | AL13: =AJ13-AG13 -> 0 | AM13: =AK13-AH13 -> 0 | AN13: =AM13-AVERAGE($AM$4:$AM$19) -> 2.3663363e-14
A14: Phiri, A. T., Weil, R. R., Yobe, G., Msaky, J. J., Mrema, J., Grossman, J., & Harawa, R. (2014). Insitu assessment of soil nitrate-nitrogen in the pigeon pea-groundnut intercropping-maize rotation system: implications on nitrogen management for increased maize productivity. International Research Journal of Agricultural Science and Soil Science, 4(2), 13-29. | B14: Phiri et al. 2014 | C14: Phiri et al. 2014b | D14: Improved Multiple | E14: Chitedze, Malawi | F14: Tropical Montane | G14: -13.989778 | H14: 33.643556 | I14: 40848 | J14: 41365 | K14: Beans | L14: 2 | O14: 1.25 | P14: =10000*W14*U14*(O14/100) -> 34.325 | S14: 1.63 | T14: =10000*X14*U14*(S14/100) -> 44.7598 | U14: 0.2 | V14: Walkley Black | W14: 1.373 | X14: 1.373 | Y14: Soilgrids | Z14: Luvisols | AA14: Sandy Clay Loam | AB14: 25.886111 | AC14: Soilgrids | AD14: T6 = Long Duration Pigeon Pea + Groundnuts | AE14: 4.667 | AF14: 1 | AG14: =T14-P14 -> 10.4348 | AH14: =AG14/L14 -> 5.2174 | AI14: 44.7598 | AJ14: =AI14-P14 -> 10.4348 | AK14: =AJ14/L14 -> 5.2174 | AL14: =AJ14-AG14 -> -9.9475983e-14 | AM14: =AK14-AH14 -> -4.9737992e-14 | AN14: =AM14-AVERAGE($AM$4:$AM$19) -> -2.6074629e-14
A15: Rajput, A., Memon, M., Memon, K. S., Sial, T. A., & Laghari, H. B. (2022). Integrated nutrient management in banana: comparative role of fym and composted pressmud for the improvement of soil properties.¬†Pakistan Journal of Botany,¬†54(1), 355-362. | B15: Rajput et al. 2022 | C15: Rajput et al. 2022b | D15: Improved Multiple | E15: Haji Khaman Nizamani, Pakistan | F15: Tropical Dry | G15: 25.518119 | H15: 68.669563 | I15: 43862 | J15: 44255 | K15: Banana | L15: 1 | M15: OM (%) | N15: 0.6 | O15: =N15/1.72 -> 0.34883721 | P15: =10000*W15*U15*(O15/100) -> 15.572093 | Q15: OM (%) | R15: =S15*1.72 -> 0.8342 | S15: 0.485 | T15: =10000*X15*U15*(S15/100) -> 21.6504 | U15: 0.3 | V15: Walkley Black | W15: 1.488 | X15: 1.488 | Y15: Soilgrids | Z15: Cambisols | AA15: Clay Loam | AB15: 39.927441 | AC15: Soilgrids | AD15: T = 500-187-0 NPK + composted pressmud (CPM) at 20 t ha-1 | AE15: 4.667 | AF15: 1 | AG15: =T15-P15 -> 6.078307 | AH15: =AG15/L15 -> 6.078307 | AI15: 21.6504 | AJ15: =AI15-P15 -> 6.078307 | AK15: =AJ15/L15 -> 6.078307 | AL15: =AJ15-AG15 -> -9.9475983e-14 | AM15: =AK15-AH15 -> -9.9475983e-14 | AN15: =AM15-AVERAGE($AM$4:$AM$19) -> -7.581262e-14
A16: Roohi, M., Arif, M. S., Guillaume, T., Yasmeen, T., Riaz, M., Shakoor, A., ... & Bragazza, L. (2022). Role of fertilization regime on soil carbon sequestration and crop yield in a maize-cowpea intercropping system on low fertility soils.¬†Geoderma,¬†428, 11 | B16: Roohi et al. 2022 | C16: Roohi et al. 2022 | D16: Improved Multiple | E16: Dialgarh, Pakistan | F16: Warm Temperate Dry | G16: 31.55 | H16: 73.1167 | I16: 42095 | J16: 43008 | K16: Maize | L16: 2 | M16: g/kg | N16: 5.8 | O16: =N16/10 -> 0.58 | P16: =10000*W16*U16*(O16/100) -> 17.748 | Q16: g/kg | R16: 10.8 | S16: =R16/10 -> 1.08 | T16: =10000*X16*U16*(S16/100) -> 32.832 | U16: 0.2 | V16: Walkley Black | W16: 1.53 | X16: 1.52 | Y16: Paper-reported | Z16: Cambisols | AA16: Loam | AB16: 21.235965 | AC16: Soilgrids | AD16: T = NPKEC: multi-nutrient enriched compost fertilization + Maize monocrop | AE16: 4.667 | AF16: 1 | AG16: =T16-P16 -> 15.084 | AH16: =AG16/L16 -> 7.542 | AI16: 32.832 | AJ16: =AI16-P16 -> 15.084 | AK16: =AJ16/L16 -> 7.542 | AL16: =AJ16-AG16 -> -9.9475983e-14 | AM16: =AK16-AH16 -> -4.9737992e-14 | AN16: =AM16-AVERAGE($AM$4:$AM$19) -> -2.6074629e-14
A17: Sireesha, P. G., Padmaja, G., Babu, M. V. S., & Rao, P. (2017). Effect of long-term fertilization on soil enzymetion on soil enzyme activities under groundnut based cropping system. An International quarterly journal of life sciences, 12(3), 1755-1758. | B17: Sireesha et al. 2017 | C17: Sireesha et al. 2017b | D17: Improved Multiple | E17: Katiganikalva, Andhra Pradesh, India | F17: Tropical Dry | G17: 14.62 | H17: 77.52 | I17: 31199 | J17: 41943 | K17: Beans | L17: 29 | O17: 0.5 | P17: =10000*W17*U17*(O17/100) -> 15.31 | S17: 0.67 | T17: =10000*X17*U17*(S17/100) -> 20.5154 | U17: 0.2 | V17: Walkley Black | W17: 1.531 | X17: 1.531 | Y17: Soilgrids | Z17: Vertisols | AA17: Clay Loam | AB17: 33.742424 | AC17: Soilgrids | AD17: T5 = FYM@5tha-1 | AE17: 4.667 | AF17: 1 | AG17: =T17-P17 -> 5.2054 | AH17: =AG17/L17 -> 0.17949655 | AI17: 20.5154 | AJ17: =AI17-P17 -> 5.2054 | AK17: =AJ17/L17 -> 0.17949655 | AL17: =AJ17-AG17 -> -6.9988459e-13 | AM17: =AK17-AH17 -> -2.4119595e-14 | AN17: =AM17-AVERAGE($AM$4:$AM$19) -> -4.5623227e-16
A18: Swanepoel, C. M., Rötter, R. P., Van der Laan, M., Annandale, J. G., Beukes, D. J., du Preez, C. C., ... & Hoffmann, M. P. (2018). The benefits of conservation agriculture on soil organic carbon and yield in southern Africa are site-specific. Soil and Tillage Research, 183, 72-82. | B18: Swanepoel et al. 2018 | C18: Swanepoel et al. 2018c | D18: Improved Multiple | E18: Buffelsvallei, South Africa | F18: Warm Temperate Dry | G18: -26.495 | H18: 26.601944 | I18: 39753 | J18: 41759 | K18: Maize | L18: 6 | O18: =(0.45+0.41)/2 -> 0.43 | P18: =10000*W18*U18*(O18/100) -> 20.64 | S18: 0.41 | T18: =10000*X18*U18*(S18/100) -> 19.68 | U18: 0.3 | V18: Walkley and Black | W18: 1.6 | X18: 1.6 | Y18: Paper-reported | Z18: unknown | AA18: Sandy Clay Loam | AB18: =(17+22)/2 -> 19.5 | AC18: Paper-reported | AD18: b = Maize sole crop reduced tillage | AE18: 4.667 | AF18: 1 | AG18: =T18-P18 -> -0.96 | AH18: =AG18/L18 -> -0.16 | AI18: 19.68 | AJ18: =AI18-P18 -> -0.96 | AK18: =AJ18/L18 -> -0.16 | AL18: =AJ18-AG18 -> -9.5923269e-14 | AM18: =AK18-AH18 -> -1.5987212e-14 | AN18: =AM18-AVERAGE($AM$4:$AM$19) -> 7.6761514e-15
A19: Swanepoel, C. M., Rötter, R. P., Van der Laan, M., Annandale, J. G., Beukes, D. J., du Preez, C. C., ... & Hoffmann, M. P. (2018). The benefits of conservation agriculture on soil organic carbon and yield in southern Africa are site-specific. Soil and Tillage Research, 183, 72-82. | B19: Swanepoel et al. 2018 | C19: Swanepoel et al. 2018d | D19: Improved Multiple | E19: Zeekoegat, South Africa | F19: Warm Temperate Dry | G19: -25.615278 | H19: 28.315556 | I19: 39753 | J19: 41394 | K19: Maize | L19: 5 | O19: =(1.286+2*1.292)/3 -> 1.29 | P19: =10000*W19*U19*(O19/100) -> 56.115 | S19: 1.33 | T19: =10000*X19*U19*(S19/100) -> 57.855 | U19: 0.3 | V19: Walkley and Black | W19: =(1.4+1.5)/2 -> 1.45 | X19: =(1.4+1.5)/2 -> 1.45 | Y19: Paper-reported | Z19: unknown | AA19: Sandy Clay Loam | AB19: =(44*2+45)/3 -> 44.333333 | AC19: Paper-reported | AD19: b = Maize sole crop reduced tillage | AE19: 4.667 | AF19: 1 | AG19: =T19-P19 -> 1.74 | AH19: =AG19/L19 -> 0.348 | AI19: 57.855 | AJ19: =AI19-P19 -> 1.74 | AK19: =AJ19/L19 -> 0.348 | AL19: =AJ19-AG19 -> 1.9895197e-13 | AM19: =AK19-AH19 -> 3.9745984e-14 | AN19: =AM19-AVERAGE($AM$4:$AM$19) -> 6.3409347e-14
A21: Data by Journal Article
A22: Paper Name | B22: Number of Samples | C22: Climate Zone | D22: Carbon Change Standard Deviation (tons/ha) | E22: Duration of Practice (Average if Multiple Trials) | F22: Yearly Carbon Change Standard Deviation (tons/ha/year)
A23: Babu et al. 2016 | B23: 1 | C23: Tropical Dry | D23: 4.667 | E23: 28 | F23: =D23/E23 -> 0.16667857
A24: Bhalerao et al. 2009 | B24: 1 | C24: Tropical Dry | D24: 4.667 | E24: 3 | F24: =D24/E24 -> 1.5556667
A25: El-Azeim et al. 2020 | B25: 1 | C25: Warm Temperate Dry | D25: 4.667 | E25: 1 | F25: =D25/E25 -> 4.667
A26: Guo et al. 2020 | B26: 1 | C26: Warm Temperate Dry | D26: 4.667 | E26: 7 | F26: =D26/E26 -> 0.66671429
A27: Hammad et al. 2020 | B27: 3 | C27: Warm Temperate Dry | D27: 4.667 | E27: 2 | F27: =D27/E27 -> 2.3335
A28: Kuttamani and Velayudham 2017 | B28: 1 | C28: Tropical Dry | D28: 4.667 | E28: 2 | F28: =D28/E28 -> 2.3335
A29: Luo et al. 2020b | B29: 1 | C29: Tropical Montane | D29: 4.667 | E29: 2 | F29: =D29/E29 -> 2.3335
A30: Mishra and Kushwaha 2016 | B30: 1 | C30: Tropical Dry | D30: 4.667 | E30: 2 | F30: =D30/E30 -> 2.3335
A31: Nyamadzawo et al. 2008b | B31: 1 | C31: Tropical Montane | D31: 4.667 | E31: 2 | F31: =D31/E31 -> 2.3335
A32: Patil et al. 2015b | B32: 1 | C32: Tropical Dry | D32: 4.667 | E32: 1 | F32: =D32/E32 -> 4.667
A33: Phiri et al. 2014 | B33: 1 | C33: Tropical Montane | D33: 4.667 | E33: 2 | F33: =D33/E33 -> 2.3335
A34: Rajput et al. 2022 | B34: 1 | C34: Tropical Dry | D34: 4.667 | E34: 1 | F34: =D34/E34 -> 4.667
... A36: Sireesha et al. 2017 | B36: 1 | C36: Tropical Dry | D36: 4.667 | E36: 29 | F36: =D36/E36 -> 0.16093103
A37: Swanepoel et al. 2018 | B37: 2 | C37: Warm Temperate Dry | D37: 4.667 | E37: =AVERAGE(L16:L17) -> 15.5 | F37: =SQRT(AVERAGE(((AE18/L18)^2),((AE19/L19)^2))) -> 0.859145
A40: Pooled Measurement Uncertainty
A41: Yearly Pooled Measurement Uncertainty (tons/ha/year)
A42: {=SQRT(SUM((F23:F37)^2 *( B23:B37 -1)) / (SUM(B23:B37 -1)))} -> 1.9688046
A44: Pooled Measurement Uncertainty Comparison: Bias of each paper must be less than the PMU
A45: Paper Name | B45: Yearly Carbon Change Bias (tons/ha/year) | C45: Pass/Fail PMU Test (Yearly Carbon Change)
...

Sheet Sampling & Combined Error
A2: Soil Type | B2: Representative Area | C2: Samples | D2: Prediction (RothC Baseline 2025) | E2: Field-measurement (2025) | F2: Variance (inherent) | G2: Difference | H2: Variance (calculated)
A3: Caltic Vertisols | B3: =C3/$C$9 * 45000*0.2 -> 1179.3103 | C3: 38 | D3: 3.4929559 | E3: 32.024334 | F3: 0.18022363 | G3: =E3-D3 -> 28.531378 | H3: =(B3^2)/(C3*(C3-1))*G3^2 -> 805223.43
A4: Dystric Leptosol | B4: =C4/$C$9 * 45000*0.2 -> 6889.6552 | C4: 222 | D4: 3.4929559 | E4: 30.825857 | F4: 0.17883185 | G4: =E4-D4 -> 27.332901 | H4: =(B4^2)/(C4*(C4-1))*G4^2 -> 722805.04
A5: Eutric Fluvisol | B5: =C5/$C$9 * 45000*0.2 -> 558.62069 | C5: 18 | D5: 3.4929559 | E5: 34.187851 | F5: 0.17446765 | G5: =E5-D5 -> 30.694895 | H5: =(B5^2)/(C5*(C5-1))*G5^2 -> 960826.39
A6: Ferric Lixosols | B6: =C6/$C$9 * 45000*0.2 -> 124.13793 | C6: 4 | D6: 3.4929559 | E6: 54.944761 | F6: 0.09569625 | G6: =E6-D6 -> 51.451805 | H6: =(B6^2)/(C6*(C6-1))*G6^2 -> 3399609.2
A7: Cambic Arenosols | B7: =C7/$C$9 * 45000*0.2 -> 124.13793 | C7: 4 | D7: 3.4929559 | E7: 42.938313 | F7: 0.091608563 | G7: =E7-D7 -> 39.445357 | H7: =(B7^2)/(C7*(C7-1))*G7^2 -> 1998110.7
A8: Dystric Plinthosols | B8: =C8/$C$9 * 45000*0.2 -> 124.13793 | C8: 4 | D8: 3.4929559 | E8: 19.942913 | F8: 0.02167425 | G8: =E8-D8 -> 16.449957 | H8: =(B8^2)/(C8*(C8-1))*G8^2 -> 347502
A9: Totals | B9: =SUM(B3:B8) -> 9000 | C9: =SUM(C3:C8) -> 290 | H9: =SUM(H3:H8) -> 8234076.7
D11: Baseline Scenario (after 2025 field-sampling)
D12: Baseline Sampling Error (tC/ha/yr)^2 | E12: =H9/(B9^2) -> 0.10165527
D13: Model Error (tC/ha/yr)^2 | E13: ='Baseline Model Error'!B80^2 + 'Project Model Error'!B89^2 -> 0.17414835
D14: Total Error (tC/ha/yr)^2 | E14: =SUM(E12:E13) -> 0.27580362
